Workbook

Sheet contagens
A1: ="n = "&COUNTA(A2:A1014) -> n = 135 | B1: TAG | C1: Periodo | D1: Transposição | E1: Coleta | F1: Data | G1: Rio | H1: Habitat=Pote | I1: ="Alíquota = "&SUM(I2:I136) -> Alíquota = 2700 | J1: ="Amostras = "&SUM(J2:J136) -> Amostras = 60
A2: PONTO1 | B2: S-PR-A-P1-C1-H1 | C2: seco | D2: pre | E2: 1 | F2: 43767 | G2: Jaguaribe | H2: 1 | I2: 20 | J2: 0
A3: PONTO1 | B3: S-PR-A-P1-C1-H2 | C3: seco | D3: pre | E3: 1 | F3: 43767 | G3: Jaguaribe | H3: 2 | I3: 20 | J3: 0
A4: PONTO1 | B4: S-PR-A-P1-C1-H3 | C4: seco | D4: pre | E4: 1 | F4: 43767 | G4: Jaguaribe | H4: 3 | I4: 20 | J4: 0
A5: PONTO2 | B5: S-PR-A-P2-C1-H1 | C5: seco | D5: pre | E5: 1 | F5: 43768 | G5: Jaguaribe | H5: 1 | I5: 20 | J5: 0
A6: PONTO2 | B6: S-PR-A-P2-C1-H2 | C6: seco | D6: pre | E6: 1 | F6: 43768 | G6: Jaguaribe | H6: 2 | I6: 20 | J6: 0
A7: PONTO2 | B7: S-PR-A-P2-C1-H3 | C7: seco | D7: pre | E7: 1 | F7: 43768 | G7: Jaguaribe | H7: 3 | I7: 20 | J7: 0
A8: PONTO3 | B8: S-PR-A-P3-C1-H1 | C8: seco | D8: pre | E8: 1 | F8: 43769 | G8: Jaguaribe | H8: 1 | I8: 20 | J8: 0
A9: PONTO3 | B9: S-PR-A-P3-C1-H2 | C9: seco | D9: pre | E9: 1 | F9: 43769 | G9: Jaguaribe | H9: 2 | I9: 20 | J9: 0
A10: PONTO3 | B10: S-PR-A-P3-C1-H3 | C10: seco | D10: pre | E10: 1 | F10: 43769 | G10: Jaguaribe | H10: 3 | I10: 20 | J10: 0
A11: PONTO4 | B11: S-PR-M-P4-C1-H1 | C11: seco | D11: pre | E11: 1 | F11: 43769 | G11: Jaguaribe | H11: 1 | I11: 20 | J11: 0
A12: PONTO4 | B12: S-PR-M-P4-C1-H2 | C12: seco | D12: pre | E12: 1 | F12: 43769 | G12: Jaguaribe | H12: 2 | I12: 20 | J12: 0
A13: PONTO4 | B13: S-PR-M-P4-C1-H3 | C13: seco | D13: pre | E13: 1 | F13: 43769 | G13: Jaguaribe | H13: 3 | I13: 20 | J13: 0
... A136: PONTO9 | B136: S-PS-B-P9-C1-H3 | C136: seco | D136: pos | E136: 5 | F136: 45964 | G136: Jaguaribe | H136: 3 | I136: 20 | J136: 20

Sheet jaguaribe_80ml
A1: ="sum= "&SUM(B3:BM50) -> sum= 46828 | B1: Alona isabellae Sousa, Elmoor-Loureiro & Santos 2016 | C1: Biapertura ossiani (Sinev, 1998) Sinev, 2020 | D1: Bdelloidea | E1: Brachionus angularis Gosse, 1851 | F1: Brachionus calyciflorus Pallas, 1766 | G1: Brachionus caudatus Barrois & Daday, 1894 | H1: Brachionus falcatus Zacharias, 1898 | I1: Brachionus havanaensis Rousselet, 1911 | J1: Brachionus quadridentatus Hermann, 1783 | K1: Cephalodella sp. | L1: Ceriodaphinia sp. | M1: Copepodite | N1: Coronatella serratalhadensis Sousa, Elmoor-Loureiro & Santos, 2015 | O1: Diaphanosoma birgei Korínek, 1981 | P1: Dicranophorus sp. | Q1: Ephemeroporus barroisi (Richard, 1894) | R1: Ephemeroporus hybridus (Daday, 1905) | S1: Ephemeroporus tridentatus (Bergamin, 1939) | T1: Epiphanes macroura (Barrois & Daday, 1894) | U1: Filinia longiseta (Ehrenberg, 1834) | V1: Filinia opoliensis (Zacharias, 1898) | W1: Hexarthra intermedia (Wiszniewski, 1929) | X1: Keratella americana Carlin, 1943 | Y1: Keratella cochlearis (Gosse, 1851) | Z1: Keratella lenzi Hauer, 1953 | AA1: Keratella tropica (Apstein, 1907) | AB1: Kurzia polyspina Hudec, 2000 | AC1: Lecane aculeata (Jakubski, 1912) | AD1: Lecane bulla (Gosse, 1851) | AE1: Lecane cornuta (Müller, 1786) | AF1: Lecane curvicornis (Murray, 1913) | AG1: Lecane furcata (Murray, 1913) | AH1: Lecane leontina (Turner, 1892) | AI1: Lecane luna (Müller, 1776) | AJ1: Lecane lunaris (Ehrenberg, 1832) | AK1: Lecane papuana (Murray, 1913) | AL1: Lecane quadridentata (Ehrenberg, 1830) | AM1: Lepadella ovalis (Müller, 1786) | AN1: Lepadella patella (Müller, 1773) | AO1: Leydigiopsis curvirostris Sars, 1901 | AP1: Leydigia striata Berabén, 1939 | AQ1: Macrochaetus sericus (Thorpe, 1893) | AR1: Macrothrix laticornis (Jurine, 1820) | AS1: Thermocyclops decipiens (Kiefer, 1929) | AT1: Nauplii | AU1: Notodiaptomus sp. | AV1: Oxyurella ciliata Bergamin, 1939 | AW1: Oxyurella longicaudis (Birge, 1910) | AX1: Plationus patulus (Müller, 1786) | AY1: Plationus patulus subsp. macracanthus (Daday, 1786) | AZ1: Platyias leloupi Gillard, 1957 | BA1: Platyias quadricornis (Ehrenberg, 1832) | BB1: Polyarthra vulgaris Carlin, 1943 | BC1: Testudinella patina (Hermann, 1783) | BD1: Trichocerca sp. | BE1: Trichotria tetractis (Ehrenberg, 1830)
A2: ="m = "&COUNTA(A3:A1014) -> m = 135 | B2: Alo.isabellae | C2: Bia.ossiani | D2: Bdelloidea | E2: Bra.angularis | F2: Bra.calyciflorus | G2: Bra.caudatus | H2: Bra.falcatus | I2: Bra. Havanaensis | J2: Bra.quadridentatus | K2: Cephalodella.sp | L2: Ceriodaphinia.sp | M2: Copepodite | N2: Cor.serratalhadensis | O2: Dia.birgei | P2: Dicranophorus.sp | Q2: Eph.barroisi | R2: Eph.hybridus | S2: Eph.tridentatus | T2: Epi.macroura | U2: Fil.longiseta | V2: Fil.opoliensis | W2: Hex.intermedia | X2: Ker.americana | Y2: Ker.cochlearis | Z2: Ker.lenzi | AA2: Ker.tropica | AB2: Kur.polyspina | AC2: Lec.aculeata | AD2: Lec.bulla | AE2: Lec.cornuta | AF2: Lec.curvicornis | AG2: Lec.furcata | AH2: Lec.leontina | AI2: Lec.luna | AJ2: Lec.lunaris | AK2: Lec.papuana | AL2: Lec.quadridentata | AM2: Lep.ovalis | AN2: Lep.patella | AO2: Ley.curvirostris | AP2: Ley.striata | AQ2: Mac.sericus | AR2: Mac.laticornis | AS2: The.decipiens | AT2: Nauplii | AU2: Notodiaptomus.sp | AV2: Oxy.ciliata | AW2: Oxy.longicaudis | AX2: Pla.patulus | AY2: Pla.macracanthus | AZ2: Pla.leloupi | BA2: Pla.quadricornis | BB2: Pol.vulgaris | BC2: Tes.patina | BD2: Trichocerca.sp | BE2: Tri.tetractis
A3: S-PR-A-P1-C1-H1 | B3: 0 | C3: 0 | D3: 39 | E3: 0 | F3: 0 | G3: 0 | H3: 0 | I3: 0 | J3: 0 | K3: 22 | L3: 0 | M3: 190 | N3: 0 | O3: 0 | P3: 0 | Q3: 0 | R3: 0 | S3: 0 | T3: 123 | U3: 1 | V3: 5 | W3: 1 | X3: 56 | Y3: 2 | Z3: 0 | AA3: 142 | AB3: 0 | AC3: 0 | AD3: 2 | AE3: 0 | AF3: 0 | AG3: 0 | AH3: 0 | AI3: 0 | AJ3: 0 | AK3: 0 | AL3: 0 | AM3: 0 | AN3: 0 | AO3: 0 | AP3: 0 | AQ3: 0 | AR3: 0 | AS3: 0 | AT3: 1512 | AU3: 0 | AV3: 0 | AW3: 0 | AX3: 0 | AY3: 0 | AZ3: 0 | BA3: 0 | BB3: 0 | BC3: 0 | BD3: 0 | BE3: 0
A4: S-PR-A-P1-C1-H2 | B4: NA | C4: NA | D4: NA | E4: NA | F4: NA | G4: NA | H4: NA | I4: NA | J4: NA | K4: NA | L4: NA | M4: NA | N4: NA | O4: NA | P4: NA | Q4: NA | R4: NA | S4: NA | T4: NA | U4: NA | V4: NA | W4: NA | X4: NA | Y4: NA | Z4: NA | AA4: NA | AB4: NA | AC4: NA | AD4: NA | AE4: NA | AF4: NA | AG4: NA | AH4: NA | AI4: NA | AJ4: NA | AK4: NA | AL4: NA | AM4: NA | AN4: NA | AO4: NA | AP4: NA | AQ4: NA | AR4: NA | AS4: NA | AT4: NA | AU4: NA | AV4: NA | AW4: NA | AX4: NA | AY4: NA | AZ4: NA | BA4: NA | BB4: NA | BC4: NA | BD4: NA | BE4: NA
A5: S-PR-A-P1-C1-H3 | B5: NA | C5: NA | D5: NA | E5: NA | F5: NA | G5: NA | H5: NA | I5: NA | J5: NA | K5: NA | L5: NA | M5: NA | N5: NA | O5: NA | P5: NA | Q5: NA | R5: NA | S5: NA | T5: NA | U5: NA | V5: NA | W5: NA | X5: NA | Y5: NA | Z5: NA | AA5: NA | AB5: NA | AC5: NA | AD5: NA | AE5: NA | AF5: NA | AG5: NA | AH5: NA | AI5: NA | AJ5: NA | AK5: NA | AL5: NA | AM5: NA | AN5: NA | AO5: NA | AP5: NA | AQ5: NA | AR5: NA | AS5: NA | AT5: NA | AU5: NA | AV5: NA | AW5: NA | AX5: NA | AY5: NA | AZ5: NA | BA5: NA | BB5: NA | BC5: NA | BD5: NA | BE5: NA
A6: S-PR-A-P2-C1-H1 | B6: 0 | C6: 0 | D6: 41 | E6: 0 | F6: 0 | G6: 0 | H6: 0 | I6: 0 | J6: 0 | K6: 4 | L6: 7 | M6: 377 | N6: 0 | O6: 40 | P6: 0 | Q6: 0 | R6: 0 | S6: 0 | T6: 12 | U6: 0 | V6: 0 | W6: 3 | X6: 2 | Y6: 1 | Z6: 0 | AA6: 23 | AB6: 1 | AC6: 0 | AD6: 4 | AE6: 0 | AF6: 0 | AG6: 0 | AH6: 0 | AI6: 0 | AJ6: 0 | AK6: 0 | AL6: 0 | AM6: 0 | AN6: 0 | AO6: 0 | AP6: 0 | AQ6: 0 | AR6: 3 | AS6: 0 | AT6: 5587 | AU6: 0 | AV6: 0 | AW6: 0 | AX6: 0 | AY6: 0 | AZ6: 0 | BA6: 0 | BB6: 121 | BC6: 0 | BD6: 0 | BE6: 0
A7: S-PR-A-P2-C1-H2 | B7: NA | C7: NA | D7: NA | E7: NA | F7: NA | G7: NA | H7: NA | I7: NA | J7: NA | K7: NA | L7: NA | M7: NA | N7: NA | O7: NA | P7: NA | Q7: NA | R7: NA | S7: NA | T7: NA | U7: NA | V7: NA | W7: NA | X7: NA | Y7: NA | Z7: NA | AA7: NA | AB7: NA | AC7: NA | AD7: NA | AE7: NA | AF7: NA | AG7: NA | AH7: NA | AI7: NA | AJ7: NA | AK7: NA | AL7: NA | AM7: NA | AN7: NA | AO7: NA | AP7: NA | AQ7: NA | AR7: NA | AS7: NA | AT7: NA | AU7: NA | AV7: NA | AW7: NA | AX7: NA | AY7: NA | AZ7: NA | BA7: NA | BB7: NA | BC7: NA | BD7: NA | BE7: NA
A8: S-PR-A-P2-C1-H3 | B8: NA | C8: NA | D8: NA | E8: NA | F8: NA | G8: NA | H8: NA | I8: NA | J8: NA | K8: NA | L8: NA | M8: NA | N8: NA | O8: NA | P8: NA | Q8: NA | R8: NA | S8: NA | T8: NA | U8: NA | V8: NA | W8: NA | X8: NA | Y8: NA | Z8: NA | AA8: NA | AB8: NA | AC8: NA | AD8: NA | AE8: NA | AF8: NA | AG8: NA | AH8: NA | AI8: NA | AJ8: NA | AK8: NA | AL8: NA | AM8: NA | AN8: NA | AO8: NA | AP8: NA | AQ8: NA | AR8: NA | AS8: NA | AT8: NA | AU8: NA | AV8: NA | AW8: NA | AX8: NA | AY8: NA | AZ8: NA | BA8: NA | BB8: NA | BC8: NA | BD8: NA | BE8: NA
A9: S-PR-A-P3-C1-H1 | B9: 0 | C9: 0 | D9: 132 | E9: 0 | F9: 2205 | G9: 0 | H9: 0 | I9: 4650 | J9: 0 | K9: 0 | L9: 0 | M9: 222 | N9: 0 | O9: 339 | P9: 0 | Q9: 0 | R9: 0 | S9: 0 | T9: 279 | U9: 0 | V9: 0 | W9: 0 | X9: 0 | Y9: 0 | Z9: 0 | AA9: 15 | AB9: 0 | AC9: 0 | AD9: 0 | AE9: 0 | AF9: 0 | AG9: 0 | AH9: 0 | AI9: 0 | AJ9: 0 | AK9: 0 | AL9: 0 | AM9: 0 | AN9: 0 | AO9: 0 | AP9: 0 | AQ9: 0 | AR9: 60 | AS9: 1 | AT9: 435 | AU9: 0 | AV9: 0 | AW9: 0 | AX9: 0 | AY9: 0 | AZ9: 0 | BA9: 0 | BB9: 0 | BC9: 0 | BD9: 0 | BE9: 0
A10: S-PR-A-P3-C1-H2 | B10: NA | C10: NA | D10: NA | E10: NA | F10: NA | G10: NA | H10: NA | I10: NA | J10: NA | K10: NA | L10: NA | M10: NA | N10: NA | O10: NA | P10: NA | Q10: NA | R10: NA | S10: NA | T10: NA | U10: NA | V10: NA | W10: NA | X10: NA | Y10: NA | Z10: NA | AA10: NA | AB10: NA | AC10: NA | AD10: NA | AE10: NA | AF10: NA | AG10: NA | AH10: NA | AI10: NA | AJ10: NA | AK10: NA | AL10: NA | AM10: NA | AN10: NA | AO10: NA | AP10: NA | AQ10: NA | AR10: NA | AS10: NA | AT10: NA | AU10: NA | AV10: NA | AW10: NA | AX10: NA | AY10: NA | AZ10: NA | BA10: NA | BB10: NA | BC10: NA | BD10: NA | BE10: NA
A11: S-PR-A-P3-C1-H3 | B11: NA | C11: NA | D11: NA | E11: NA | F11: NA | G11: NA | H11: NA | I11: NA | J11: NA | K11: NA | L11: NA | M11: NA | N11: NA | O11: NA | P11: NA | Q11: NA | R11: NA | S11: NA | T11: NA | U11: NA | V11: NA | W11: NA | X11: NA | Y11: NA | Z11: NA | AA11: NA | AB11: NA | AC11: NA | AD11: NA | AE11: NA | AF11: NA | AG11: NA | AH11: NA | AI11: NA | AJ11: NA | AK11: NA | AL11: NA | AM11: NA | AN11: NA | AO11: NA | AP11: NA | AQ11: NA | AR11: NA | AS11: NA | AT11: NA | AU11: NA | AV11: NA | AW11: NA | AX11: NA | AY11: NA | AZ11: NA | BA11: NA | BB11: NA | BC11: NA | BD11: NA | BE11: NA
A12: S-PR-M-P4-C1-H1 | B12: 0 | C12: 0 | D12: 12 | E12: 0 | F12: 326 | G12: 0 | H12: 0 | I12: 1210 | J12: 0 | K12: 2 | L12: 0 | M12: 20 | N12: 0 | O12: 36 | P12: 0 | Q12: 0 | R12: 0 | S12: 0 | T12: 19 | U12: 0 | V12: 0 | W12: 0 | X12: 0 | Y12: 0 | Z12: 0 | AA12: 0 | AB12: 0 | AC12: 0 | AD12: 1 | AE12: 0 | AF12: 1 | AG12: 0 | AH12: 0 | AI12: 3 | AJ12: 0 | AK12: 0 | AL12: 0 | AM12: 0 | AN12: 0 | AO12: 0 | AP12: 0 | AQ12: 0 | AR12: 82 | AS12: 2 | AT12: 31 | AU12: 0 | AV12: 0 | AW12: 0 | AX12: 0 | AY12: 0 | AZ12: 0 | BA12: 1 | BB12: 1 | BC12: 0 | BD12: 0 | BE12: 0
A13: S-PR-M-P4-C1-H2 | B13: NA | C13: NA | D13: NA | E13: NA | F13: NA | G13: NA | H13: NA | I13: NA | J13: NA | K13: NA | L13: NA | M13: NA | N13: NA | O13: NA | P13: NA | Q13: NA | R13: NA | S13: NA | T13: NA | U13: NA | V13: NA | W13: NA | X13: NA | Y13: NA | Z13: NA | AA13: NA | AB13: NA | AC13: NA | AD13: NA | AE13: NA | AF13: NA | AG13: NA | AH13: NA | AI13: NA | AJ13: NA | AK13: NA | AL13: NA | AM13: NA | AN13: NA | AO13: NA | AP13: NA | AQ13: NA | AR13: NA | AS13: NA | AT13: NA | AU13: NA | AV13: NA | AW13: NA | AX13: NA | AY13: NA | AZ13: NA | BA13: NA | BB13: NA | BC13: NA | BD13: NA | BE13: NA
A14: S-PR-M-P4-C1-H3 | B14: NA | C14: NA | D14: NA | E14: NA | F14: NA | G14: NA | H14: NA | I14: NA | J14: NA | K14: NA | L14: NA | M14: NA | N14: NA | O14: NA | P14: NA | Q14: NA | R14: NA | S14: NA | T14: NA | U14: NA | V14: NA | W14: NA | X14: NA | Y14: NA | Z14: NA | AA14: NA | AB14: NA | AC14: NA | AD14: NA | AE14: NA | AF14: NA | AG14: NA | AH14: NA | AI14: NA | AJ14: NA | AK14: NA | AL14: NA | AM14: NA | AN14: NA | AO14: NA | AP14: NA | AQ14: NA | AR14: NA | AS14: NA | AT14: NA | AU14: NA | AV14: NA | AW14: NA | AX14: NA | AY14: NA | AZ14: NA | BA14: NA | BB14: NA | BC14: NA | BD14: NA | BE14: NA
A15: S-PR-M-P5-C1-H1 | B15: 1 | C15: 0 | D15: 50 | E15: 0 | F15: 168 | G15: 0 | H15: 0 | I15: 215 | J15: 0 | K15: 3 | L15: 0 | M15: 16 | N15: 0 | O15: 19 | P15: 0 | Q15: 0 | R15: 0 | S15: 0 | T15: 21 | U15: 0 | V15: 0 | W15: 0 | X15: 0 | Y15: 0 | Z15: 0 | AA15: 0 | AB15: 0 | AC15: 1 | AD15: 5 | AE15: 0 | AF15: 26 | AG15: 0 | AH15: 0 | AI15: 2 | AJ15: 42 | AK15: 0 | AL15: 3 | AM15: 0 | AN15: 0 | AO15: 0 | AP15: 0 | AQ15: 1 | AR15: 24 | AS15: 0 | AT15: 22 | AU15: 0 | AV15: 0 | AW15: 1 | AX15: 17 | AY15: 0 | AZ15: 0 | BA15: 0 | BB15: 0 | BC15: 6 | BD15: 0 | BE15: 0
A16: S-PR-M-P5-C1-H2 | B16: NA | C16: NA | D16: NA | E16: NA | F16: NA | G16: NA | H16: NA | I16: NA | J16: NA | K16: NA | L16: NA | M16: NA | N16: NA | O16: NA | P16: NA | Q16: NA | R16: NA | S16: NA | T16: NA | U16: NA | V16: NA | W16: NA | X16: NA | Y16: NA | Z16: NA | AA16: NA | AB16: NA | AC16: NA | AD16: NA | AE16: NA | AF16: NA | AG16: NA | AH16: NA | AI16: NA | AJ16: NA | AK16: NA | AL16: NA | AM16: NA | AN16: NA | AO16: NA | AP16: NA | AQ16: NA | AR16: NA | AS16: NA | AT16: NA | AU16: NA | AV16: NA | AW16: NA | AX16: NA | AY16: NA | AZ16: NA | BA16: NA | BB16: NA | BC16: NA | BD16: NA | BE16: NA
A17: S-PR-M-P5-C1-H3 | B17: NA | C17: NA | D17: NA | E17: NA | F17: NA | G17: NA | H17: NA | I17: NA | J17: NA | K17: NA | L17: NA | M17: NA | N17: NA | O17: NA | P17: NA | Q17: NA | R17: NA | S17: NA | T17: NA | U17: NA | V17: NA | W17: NA | X17: NA | Y17: NA | Z17: NA | AA17: NA | AB17: NA | AC17: NA | AD17: NA | AE17: NA | AF17: NA | AG17: NA | AH17: NA | AI17: NA | AJ17: NA | AK17: NA | AL17: NA | AM17: NA | AN17: NA | AO17: NA | AP17: NA | AQ17: NA | AR17: NA | AS17: NA | AT17: NA | AU17: NA | AV17: NA | AW17: NA | AX17: NA | AY17: NA | AZ17: NA | BA17: NA | BB17: NA | BC17: NA | BD17: NA | BE17: NA
A18: S-PR-M-P6-C1-H1 | B18: 2 | C18: 0 | D18: 1 | E18: 0 | F18: 38 | G18: 0 | H18: 0 | I18: 40 | J18: 0 | K18: 0 | L18: 0 | M18: 5 | N18: 2 | O18: 1 | P18: 0 | Q18: 0 | R18: 0 | S18: 0 | T18: 5 | U18: 0 | V18: 0 | W18: 0 | X18: 0 | Y18: 0 | Z18: 0 | AA18: 0 | AB18: 0 | AC18: 0 | AD18: 1 | AE18: 0 | AF18: 2 | AG18: 2 | AH18: 0 | AI18: 1 | AJ18: 11 | AK18: 0 | AL18: 2 | AM18: 0 | AN18: 1 | AO18: 0 | AP18: 0 | AQ18: 0 | AR18: 8 | AS18: 1 | AT18: 11 | AU18: 0 | AV18: 0 | AW18: 0 | AX18: 3 | AY18: 0 | AZ18: 0 | BA18: 0 | BB18: 0 | BC18: 8 | BD18: 0 | BE18: 0
A19: S-PR-M-P6-C1-H2 | B19: NA | C19: NA | D19: NA | E19: NA | F19: NA | G19: NA | H19: NA | I19: NA | J19: NA | K19: NA | L19: NA | M19: NA | N19: NA | O19: NA | P19: NA | Q19: NA | R19: NA | S19: NA | T19: NA | U19: NA | V19: NA | W19: NA | X19: NA | Y19: NA | Z19: NA | AA19: NA | AB19: NA | AC19: NA | AD19: NA | AE19: NA | AF19: NA | AG19: NA | AH19: NA | AI19: NA | AJ19: NA | AK19: NA | AL19: NA | AM19: NA | AN19: NA | AO19: NA | AP19: NA | AQ19: NA | AR19: NA | AS19: NA | AT19: NA | AU19: NA | AV19: NA | AW19: NA | AX19: NA | AY19: NA | AZ19: NA | BA19: NA | BB19: NA | BC19: NA | BD19: NA | BE19: NA
A20: S-PR-M-P6-C1-H3 | B20: NA | C20: NA | D20: NA | E20: NA | F20: NA | G20: NA | H20: NA | I20: NA | J20: NA | K20: NA | L20: NA | M20: NA | N20: NA | O20: NA | P20: NA | Q20: NA | R20: NA | S20: NA | T20: NA | U20: NA | V20: NA | W20: NA | X20: NA | Y20: NA | Z20: NA | AA20: NA | AB20: NA | AC20: NA | AD20: NA | AE20: NA | AF20: NA | AG20: NA | AH20: NA | AI20: NA | AJ20: NA | AK20: NA | AL20: NA | AM20: NA | AN20: NA | AO20: NA | AP20: NA | AQ20: NA | AR20: NA | AS20: NA | AT20: NA | AU20: NA | AV20: NA | AW20: NA | AX20: NA | AY20: NA | AZ20: NA | BA20: NA | BB20: NA | BC20: NA | BD20: NA | BE20: NA
A21: S-PR-B-P7-C1-H1 | B21: 3 | C21: 0 | D21: 27 | E21: 0 | F21: 13 | G21: 0 | H21: 0 | I21: 38 | J21: 0 | K21: 0 | L21: 0 | M21: 18 | N21: 3 | O21: 15 | P21: 0 | Q21: 4 | R21: 0 | S21: 1 | T21: 11 | U21: 0 | V21: 0 | W21: 0 | X21: 0 | Y21: 0 | Z21: 0 | AA21: 7 | AB21: 0 | AC21: 0 | AD21: 20 | AE21: 1 | AF21: 58 | AG21: 0 | AH21: 0 | AI21: 1 | AJ21: 1 | AK21: 0 | AL21: 0 | AM21: 0 | AN21: 0 | AO21: 0 | AP21: 0 | AQ21: 0 | AR21: 24 | AT21: 2171 | AU21: 7 | AV21: 0 | AW21: 0 | AX21: 5 | AY21: 0 | AZ21: 0 | BA21: 0 | BB21: 0 | BC21: 2 | BD21: 0 | BE21: 0
A22: S-PR-B-P7-C1-H2 | B22: NA | C22: NA | D22: NA | E22: NA | F22: NA | G22: NA | H22: NA | I22: NA | J22: NA | K22: NA | L22: NA | M22: NA | N22: NA | O22: NA | P22: NA | Q22: NA | R22: NA | S22: NA | T22: NA | U22: NA | V22: NA | W22: NA | X22: NA | Y22: NA | Z22: NA | AA22: NA | AB22: NA | AC22: NA | AD22: NA | AE22: NA | AF22: NA | AG22: NA | AH22: NA | AI22: NA | AJ22: NA | AK22: NA | AL22: NA | AM22: NA | AN22: NA | AO22: NA | AP22: NA | AQ22: NA | AR22: NA | AS22: NA | AT22: NA | AU22: NA | AV22: NA | AW22: NA | AX22: NA | AY22: NA | AZ22: NA | BA22: NA | BB22: NA | BC22: NA | BD22: NA | BE22: NA
A23: S-PR-B-P7-C1-H3 | B23: NA | C23: NA | D23: NA | E23: NA | F23: NA | G23: NA | H23: NA | I23: NA | J23: NA | K23: NA | L23: NA | M23: NA | N23: NA | O23: NA | P23: NA | Q23: NA | R23: NA | S23: NA | T23: NA | U23: NA | V23: NA | W23: NA | X23: NA | Y23: NA | Z23: NA | AA23: NA | AB23: NA | AC23: NA | AD23: NA | AE23: NA | AF23: NA | AG23: NA | AH23: NA | AI23: NA | AJ23: NA | AK23: NA | AL23: NA | AM23: NA | AN23: NA | AO23: NA | AP23: NA | AQ23: NA | AR23: NA | AS23: NA | AT23: NA | AU23: NA | AV23: NA | AW23: NA | AX23: NA | AY23: NA | AZ23: NA | BA23: NA | BB23: NA | BC23: NA | BD23: NA | BE23: NA
A24: S-PR-B-P8-C1-H1 | B24: 0 | C24: 0 | D24: 12 | E24: 0 | F24: 591 | G24: 105 | H24: 0 | I24: 39 | J24: 0 | K24: 12 | L24: 0 | M24: 537 | N24: 3 | O24: 27 | P24: 0 | Q24: 3 | R24: 0 | S24: 4 | T24: 6 | U24: 78 | V24: 9 | W24: 0 | X24: 0 | Y24: 0 | Z24: 0 | AA24: 9 | AB24: 0 | AC24: 0 | AD24: 0 | AE24: 8 | AF24: 0 | AG24: 0 | AH24: 0 | AI24: 0 | AJ24: 6 | AK24: 0 | AL24: 0 | AM24: 0 | AN24: 5 | AO24: 0 | AP24: 0 | AQ24: 2 | AR24: 0 | AS24: 7 | AT24: 2814 | AU24: 84 | AV24: 0 | AW24: 0 | AX24: 0 | AY24: 0 | AZ24: 0 | BA24: 0 | BB24: 81 | BC24: 0 | BD24: 0 | BE24: 0
A25: S-PR-B-P8-C1-H2 | B25: NA | C25: NA | D25: NA | E25: NA | F25: NA | G25: NA | H25: NA | I25: NA | J25: NA | K25: NA | L25: NA | M25: NA | N25: NA | O25: NA | P25: NA | Q25: NA | R25: NA | S25: NA | T25: NA | U25: NA | V25: NA | W25: NA | X25: NA | Y25: NA | Z25: NA | AA25: NA | AB25: NA | AC25: NA | AD25: NA | AE25: NA | AF25: NA | AG25: NA | AH25: NA | AI25: NA | AJ25: NA | AK25: NA | AL25: NA | AM25: NA | AN25: NA | AO25: NA | AP25: NA | AQ25: NA | AR25: NA | AS25: NA | AT25: NA | AU25: NA | AV25: NA | AW25: NA | AX25: NA | AY25: NA | AZ25: NA | BA25: NA | BB25: NA | BC25: NA | BD25: NA | BE25: NA
A26: S-PR-B-P8-C1-H3 | B26: NA | C26: NA | D26: NA | E26: NA | F26: NA | G26: NA | H26: NA | I26: NA | J26: NA | K26: NA | L26: NA | M26: NA | N26: NA | O26: NA | P26: NA | Q26: NA | R26: NA | S26: NA | T26: NA | U26: NA | V26: NA | W26: NA | X26: NA | Y26: NA | Z26: NA | AA26: NA | AB26: NA | AC26: NA | AD26: NA | AE26: NA | AF26: NA | AG26: NA | AH26: NA | AI26: NA | AJ26: NA | AK26: NA | AL26: NA | AM26: NA | AN26: NA | AO26: NA | AP26: NA | AQ26: NA | AR26: NA | AS26: NA | AT26: NA | AU26: NA | AV26: NA | AW26: NA | AX26: NA | AY26: NA | AZ26: NA | BA26: NA | BB26: NA | BC26: NA | BD26: NA | BE26: NA
A27: S-PR-B-P9-C1-H1 | B27: 0 | C27: 0 | D27: 2115 | E27: 0 | F27: 2736 | G27: 12 | H27: 0 | I27: 84 | J27: 0 | K27: 21 | L27: 0 | M27: 162 | N27: 0 | O27: 6 | P27: 0 | Q27: 0 | R27: 0 | S27: 0 | T27: 2961 | U27: 9 | V27: 0 | W27: 0 | X27: 0 | Y27: 0 | Z27: 15 | AA27: 228 | AB27: 0 | AC27: 0 | AD27: 8 | AE27: 0 | AF27: 23 | AG27: 0 | AH27: 0 | AI27: 0 | AJ27: 6 | AK27: 0 | AL27: 0 | AM27: 0 | AN27: 0 | AO27: 0 | AP27: 0 | AQ27: 0 | AR27: 0 | AS27: 0 | AT27: 270 | AU27: 4 | AV27: 0 | AW27: 0 | AX27: 0 | AY27: 0 | AZ27: 0 | BA27: 0 | BB27: 11 | BC27: 0 | BD27: 0 | BE27: 0
A28: S-PR-B-P9-C1-H2 | B28: NA | C28: NA | D28: NA | E28: NA | F28: NA | G28: NA | H28: NA | I28: NA | J28: NA | K28: NA | L28: NA | M28: NA | N28: NA | O28: NA | P28: NA | Q28: NA | R28: NA | S28: NA | T28: NA | U28: NA | V28: NA | W28: NA | X28: NA | Y28: NA | Z28: NA | AA28: NA | AB28: NA | AC28: NA | AD28: NA | AE28: NA | AF28: NA | AG28: NA | AH28: NA | AI28: NA | AJ28: NA | AK28: NA | AL28: NA | AM28: NA | AN28: NA | AO28: NA | AP28: NA | AQ28: NA | AR28: NA | AS28: NA | AT28: NA | AU28: NA | AV28: NA | AW28: NA | AX28: NA | AY28: NA | AZ28: NA | BA28: NA | BB28: NA | BC28: NA | BD28: NA | BE28: NA
A29: S-PR-B-P9-C1-H3 | B29: NA | C29: NA | D29: NA | E29: NA | F29: NA | G29: NA | H29: NA | I29: NA | J29: NA | K29: NA | L29: NA | M29: NA | N29: NA | O29: NA | P29: NA | Q29: NA | R29: NA | S29: NA | T29: NA | U29: NA | V29: NA | W29: NA | X29: NA | Y29: NA | Z29: NA | AA29: NA | AB29: NA | AC29: NA | AD29: NA | AE29: NA | AF29: NA | AG29: NA | AH29: NA | AI29: NA | AJ29: NA | AK29: NA | AL29: NA | AM29: NA | AN29: NA | AO29: NA | AP29: NA | AQ29: NA | AR29: NA | AS29: NA | AT29: NA | AU29: NA | AV29: NA | AW29: NA | AX29: NA | AY29: NA | AZ29: NA | BA29: NA | BB29: NA | BC29: NA | BD29: NA | BE29: NA
A30: C-PR-A-P1-C2-H1 | B30: 0 | C30: 0 | D30: 130 | E30: 0 | F30: 3 | G30: 0 | H30: 0 | I30: 6 | J30: 0 | K30: 4 | L30: 0 | M30: 93 | N30: 0 | O30: 0 | P30: 0 | Q30: 0 | R30: 0 | S30: 0 | T30: 11 | U30: 7 | V30: 0 | W30: 0 | X30: 0 | Y30: 0 | Z30: 0 | AA30: 70 | AB30: 0 | AC30: 0 | AD30: 2 | AE30: 0 | AF30: 0 | AG30: 0 | AH30: 0 | AI30: 0 | AJ30: 0 | AK30: 0 | AL30: 0 | AM30: 0 | AN30: 0 | AO30: 0 | AP30: 0 | AQ30: 0 | AR30: 0 | AS30: 0 | AT30: 394 | AU30: 0 | AV30: 0 | AW30: 0 | AX30: 0 | AY30: 0 | AZ30: 0 | BA30: 0 | BB30: 46 | BC30: 0 | BD30: 0 | BE30: 0
A31: C-PR-A-P1-C2-H2 | B31: 0 | C31: 0 | D31: 40 | E31: 0 | F31: 4 | G31: 0 | H31: 0 | I31: 2 | J31: 0 | K31: 6 | L31: 0 | M31: 121 | N31: 0 | O31: 0 | P31: 0 | Q31: 0 | R31: 0 | S31: 0 | T31: 21 | U31: 1 | V31: 0 | W31: 0 | X31: 0 | Y31: 0 | Z31: 0 | AA31: 52 | AB31: 0 | AC31: 0 | AD31: 1 | AE31: 0 | AF31: 0 | AG31: 0 | AH31: 0 | AI31: 0 | AJ31: 0 | AK31: 0 | AL31: 0 | AM31: 0 | AN31: 0 | AO31: 0 | AP31: 0 | AQ31: 0 | AR31: 0 | AS31: 0 | AT31: 323 | AU31: 0 | AV31: 0 | AW31: 0 | AX31: 0 | AY31: 0 | AZ31: 0 | BA31: 0 | BB31: 49 | BC31: 0 | BD31: 0 | BE31: 0
A32: C-PR-A-P1-C2-H3 | B32: 0 | C32: 0 | D32: 11 | E32: 0 | F32: 0 | G32: 0 | H32: 0 | I32: 0 | J32: 0 | K32: 0 | L32: 0 | M32: 17 | N32: 0 | O32: 1 | P32: 0 | Q32: 0 | R32: 0 | S32: 0 | T32: 0 | U32: 0 | V32: 0 | W32: 0 | X32: 0 | Y32: 0 | Z32: 0 | AA32: 3 | AB32: 0 | AC32: 0 | AD32: 0 | AE32: 0 | AF32: 0 | AG32: 0 | AH32: 0 | AI32: 0 | AJ32: 0 | AK32: 0 | AL32: 0 | AM32: 0 | AN32: 0 | AO32: 0 | AP32: 0 | AQ32: 0 | AR32: 1 | AS32: 0 | AT32: 34 | AU32: 0 | AV32: 0 | AW32: 0 | AX32: 0 | AY32: 0 | AZ32: 0 | BA32: 0 | BB32: 3 | BC32: 1 | BD32: 0 | BE32: 0
A33: C-PR-A-P2-C2-H1 | B33: 0 | C33: 0 | D33: 20 | E33: 0 | F33: 0 | G33: 2 | H33: 1 | I33: 2 | J33: 0 | K33: 3 | L33: 0 | M33: 101 | N33: 2 | O33: 4 | P33: 0 | Q33: 0 | R33: 0 | S33: 0 | T33: 1 | U33: 21 | V33: 2 | W33: 0 | X33: 0 | Y33: 0 | Z33: 0 | AA33: 15 | AB33: 0 | AC33: 0 | AD33: 6 | AE33: 1 | AF33: 0 | AG33: 0 | AH33: 1 | AI33: 0 | AJ33: 2 | AK33: 0 | AL33: 0 | AM33: 0 | AN33: 0 | AO33: 0 | AP33: 0 | AQ33: 0 | AR33: 6 | AS33: 3 | AT33: 764 | AU33: 0 | AV33: 0 | AW33: 0 | AX33: 7 | AY33: 28 | AZ33: 0 | BA33: 4 | BB33: 8 | BC33: 47 | BD33: 0 | BE33: 0
A34: C-PR-A-P2-C2-H2 | B34: 0 | C34: 0 | D34: 7 | E34: 0 | F34: 1 | G34: 1 | H34: 0 | I34: 1 | J34: 0 | K34: 0 | L34: 0 | M34: 79 | N34: 0 | O34: 16 | P34: 0 | Q34: 0 | R34: 0 | S34: 0 | T34: 3 | U34: 10 | V34: 0 | W34: 0 | X34: 0 | Y34: 0 | Z34: 0 | AA34: 1 | AB34: 0 | AC34: 0 | AD34: 3 | AE34: 1 | AF34: 0 | AG34: 0 | AH34: 10 | AI34: 3 | AJ34: 1 | AK34: 0 | AL34: 0 | AM34: 1 | AN34: 0 | AO34: 1 | AP34: 0 | AQ34: 0 | AR34: 25 | AS34: 71 | AT34: 945 | AU34: 0 | AV34: 2 | AW34: 3 | AX34: 24 | AY34: 0 | AZ34: 0 | BA34: 55 | BB34: 1 | BC34: 26 | BD34: 1 | BE34: 1
A35: C-PR-A-P2-C2-H3 | B35: 0 | C35: 0 | D35: 12 | E35: 0 | F35: 0 | G35: 3 | H35: 1 | I35: 3 | J35: 1 | K35: 2 | L35: 0 | M35: 144 | N35: 1 | O35: 3 | P35: 0 | Q35: 0 | R35: 0 | S35: 0 | T35: 4 | U35: 11 | V35: 0 | W35: 0 | X35: 0 | Y35: 0 | Z35: 0 | AA35: 13 | AB35: 0 | AC35: 0 | AD35: 4 | AE35: 2 | AF35: 3 | AG35: 0 | AH35: 3 | AI35: 2 | AJ35: 4 | AK35: 0 | AL35: 0 | AM35: 1 | AN35: 0 | AO35: 0 | AP35: 0 | AQ35: 0 | AR35: 6 | AS35: 4 | AT35: 1728 | AU35: 0 | AV35: 0 | AW35: 0 | AX35: 12 | AY35: 39 | AZ35: 0 | BA35: 6 | BB35: 3 | BC35: 38 | BD35: 1 | BE35: 0
A36: C-PR-A-P3-C2-H1 | B36: 1 | C36: 0 | D36: 10 | E36: 16 | F36: 10 | G36: 0 | H36: 80 | I36: 1 | J36: 23 | K36: 7 | L36: 0 | M36: 6 | N36: 0 | O36: 0 | P36: 0 | Q36: 0 | R36: 0 | S36: 0 | T36: 0 | U36: 104 | V36: 0 | W36: 0 | X36: 0 | Y36: 1 | Z36: 1 | AA36: 59 | AB36: 0 | AC36: 0 | AD36: 3 | AE36: 0 | AF36: 0 | AG36: 0 | AH36: 1 | AI36: 1 | AJ36: 1 | AK36: 0 | AL36: 0 | AM36: 0 | AN36: 0 | AO36: 0 | AP36: 0 | AQ36: 0 | AR36: 1 | AS36: 0 | AT36: 25 | AU36: 0 | AV36: 0 | AW36: 0 | AX36: 17 | AY36: 4 | AZ36: 1 | BA36: 5 | BB36: 3 | BC36: 3 | BD36: 1 | BE36: 0
A37: C-PR-A-P3-C2-H2 | B37: 0 | C37: 0 | D37: 4 | E37: 28 | F37: 16 | G37: 0 | H37: 78 | I37: 0 | J37: 25 | K37: 3 | L37: 0 | M37: 3 | N37: 0 | O37: 0 | P37: 0 | Q37: 0 | R37: 0 | S37: 0 | T37: 1 | U37: 84 | V37: 0 | W37: 0 | X37: 0 | Y37: 5 | Z37: 7 | AA37: 62 | AB37: 0 | AC37: 0 | AD37: 1 | AE37: 0 | AF37: 0 | AG37: 0 | AH37: 0 | AI37: 1 | AJ37: 0 | AK37: 0 | AL37: 0 | AM37: 0 | AN37: 0 | AO37: 0 | AP37: 0 | AQ37: 0 | AR37: 1 | AS37: 0 | AT37: 19 | AU37: 0 | AV37: 0 | AW37: 0 | AX37: 14 | AY37: 7 | AZ37: 0 | BA37: 6 | BB37: 2 | BC37: 10 | BD37: 1 | BE37: 0
A38: C-PR-A-P3-C2-H3 | B38: 0 | C38: 0 | D38: 2 | E38: 111 | F38: 20 | G38: 11 | H38: 135 | I38: 1 | J38: 34 | K38: 4 | L38: 0 | M38: 13 | N38: 0 | O38: 2 | P38: 1 | Q38: 0 | R38: 0 | S38: 0 | T38: 1 | U38: 535 | V38: 0 | W38: 0 | X38: 0 | Y38: 3 | Z38: 4 | AA38: 67 | AB38: 0 | AC38: 0 | AD38: 1 | AE38: 0 | AF38: 2 | AG38: 0 | AH38: 1 | AI38: 0 | AJ38: 1 | AK38: 0 | AL38: 0 | AM38: 0 | AN38: 0 | AO38: 0 | AP38: 0 | AQ38: 0 | AR38: 1 | AS38: 0 | AT38: 111 | AU38: 0 | AV38: 0 | AW38: 0 | AX38: 38 | AY38: 5 | AZ38: 0 | BA38: 6 | BB38: 7 | BC38: 4 | BD38: 0 | BE38: 0
A39: C-PR-M-P4-C2-H1 | B39: 0 | C39: 0 | D39: 14 | E39: 77 | F39: 8 | G39: 4 | H39: 84 | I39: 2 | J39: 19 | K39: 9 | L39: 0 | M39: 2 | N39: 0 | O39: 0 | P39: 0 | Q39: 0 | R39: 0 | S39: 0 | T39: 4 | U39: 111 | V39: 0 | W39: 0 | X39: 0 | Y39: 1 | Z39: 2 | AA39: 84 | AB39: 0 | AC39: 0 | AD39: 3 | AE39: 0 | AF39: 3 | AG39: 0 | AH39: 1 | AI39: 0 | AJ39: 0 | AK39: 0 | AL39: 0 | AM39: 1 | AN39: 0 | AO39: 0 | AP39: 0 | AQ39: 0 | AR39: 1 | AS39: 3 | AT39: 87 | AU39: 0 | AV39: 0 | AW39: 0 | AX39: 9 | AY39: 4 | AZ39: 0 | BA39: 1 | BB39: 0 | BC39: 8 | BD39: 1 | BE39: 0
A40: C-PR-M-P4-C2-H2 | B40: 0 | C40: 0 | D40: 4 | E40: 38 | F40: 15 | G40: 3 | H40: 71 | I40: 1 | J40: 26 | K40: 5 | L40: 0 | M40: 2 | N40: 0 | O40: 0 | P40: 0 | Q40: 0 | R40: 0 | S40: 0 | T40: 1 | U40: 70 | V40: 0 | W40: 0 | X40: 0 | Y40: 9 | Z40: 2 | AA40: 86 | AB40: 0 | AC40: 0 | AD40: 1 | AE40: 0 | AF40: 2 | AG40: 0 | AH40: 0 | AI40: 0 | AJ40: 0 | AK40: 0 | AL40: 0 | AM40: 0 | AN40: 0 | AO40: 0 | AP40: 0 | AQ40: 0 | AR40: 0 | AS40: 0 | AT40: 41 | AU40: 0 | AV40: 0 | AW40: 0 | AX40: 7 | AY40: 2 | AZ40: 0 | BA40: 2 | BB40: 0 | BC40: 21 | BD40: 0 | BE40: 0
...

Sheet densidade_hab_indL
B1: =jaguaribe_80ml!B2 -> Alo.isabellae | C1: =jaguaribe_80ml!C2 -> Bia.ossiani | D1: =jaguaribe_80ml!D2 -> Bdelloidea | E1: =jaguaribe_80ml!E2 -> Bra.angularis | F1: =jaguaribe_80ml!F2 -> Bra.calyciflorus | G1: =jaguaribe_80ml!G2 -> Bra.caudatus | H1: =jaguaribe_80ml!H2 -> Bra.falcatus | I1: =jaguaribe_80ml!I2 -> Bra. Havanaensis | ... BE1: =jaguaribe_80ml!BE2 -> Tri.tetractis
A2: S-PR-A-P1-C1-H1 | B2: =jaguaribe_80ml!B3/50 -> 0 | C2: =jaguaribe_80ml!C3/50 -> 0 | D2: =jaguaribe_80ml!D3/50 -> 0.78 | E2: =jaguaribe_80ml!E3/50 -> 0 | F2: =jaguaribe_80ml!F3/50 -> 0 | G2: =jaguaribe_80ml!G3/50 -> 0 | H2: =jaguaribe_80ml!H3/50 -> 0 | I2: =jaguaribe_80ml!I3/50 -> 0 | ... BE2: =jaguaribe_80ml!BE3/50 -> 0
A3: S-PR-A-P1-C1-H2 | B3: NA | C3: NA | D3: NA | E3: NA | F3: NA | G3: NA | H3: NA | I3: NA | J3: NA | K3: NA | L3: NA | M3: NA | N3: NA | O3: NA | P3: NA | Q3: NA | R3: NA | S3: NA | T3: NA | U3: NA | V3: NA | W3: NA | X3: NA | Y3: NA | Z3: NA | AA3: NA | AB3: NA | AC3: NA | AD3: NA | AE3: NA | AF3: NA | AG3: NA | AH3: NA | AI3: NA | AJ3: NA | AK3: NA | AL3: NA | AM3: NA | AN3: NA | AO3: NA | AP3: NA | AQ3: NA | AR3: NA | AS3: NA | AT3: NA | AU3: NA | AV3: NA | AW3: NA | AX3: NA | AY3: NA | AZ3: NA | BA3: NA | BB3: NA | BC3: NA | BD3: NA | BE3: NA
A4: S-PR-A-P1-C1-H3 | B4: NA | C4: NA | D4: NA | E4: NA | F4: NA | G4: NA | H4: NA | I4: NA | J4: NA | K4: NA | L4: NA | M4: NA | N4: NA | O4: NA | P4: NA | Q4: NA | R4: NA | S4: NA | T4: NA | U4: NA | V4: NA | W4: NA | X4: NA | Y4: NA | Z4: NA | AA4: NA | AB4: NA | AC4: NA | AD4: NA | AE4: NA | AF4: NA | AG4: NA | AH4: NA | AI4: NA | AJ4: NA | AK4: NA | AL4: NA | AM4: NA | AN4: NA | AO4: NA | AP4: NA | AQ4: NA | AR4: NA | AS4: NA | AT4: NA | AU4: NA | AV4: NA | AW4: NA | AX4: NA | AY4: NA | AZ4: NA | BA4: NA | BB4: NA | BC4: NA | BD4: NA | BE4: NA
A5: S-PR-A-P2-C1-H1 | B5: =jaguaribe_80ml!B6/50 -> 0 | C5: =jaguaribe_80ml!C6/50 -> 0 | D5: =jaguaribe_80ml!D6/50 -> 0.82 | E5: =jaguaribe_80ml!E6/50 -> 0 | F5: =jaguaribe_80ml!F6/50 -> 0 | G5: =jaguaribe_80ml!G6/50 -> 0 | H5: =jaguaribe_80ml!H6/50 -> 0 | I5: =jaguaribe_80ml!I6/50 -> 0 | ... BE5: =jaguaribe_80ml!BE6/50 -> 0
A6: S-PR-A-P2-C1-H2 | B6: NA | C6: NA | D6: NA | E6: NA | F6: NA | G6: NA | H6: NA | I6: NA | J6: NA | K6: NA | L6: NA | M6: NA | N6: NA | O6: NA | P6: NA | Q6: NA | R6: NA | S6: NA | T6: NA | U6: NA | V6: NA | W6: NA | X6: NA | Y6: NA | Z6: NA | AA6: NA | AB6: NA | AC6: NA | AD6: NA | AE6: NA | AF6: NA | AG6: NA | AH6: NA | AI6: NA | AJ6: NA | AK6: NA | AL6: NA | AM6: NA | AN6: NA | AO6: NA | AP6: NA | AQ6: NA | AR6: NA | AS6: NA | AT6: NA | AU6: NA | AV6: NA | AW6: NA | AX6: NA | AY6: NA | AZ6: NA | BA6: NA | BB6: NA | BC6: NA | BD6: NA | BE6: NA
A7: S-PR-A-P2-C1-H3 | B7: NA | C7: NA | D7: NA | E7: NA | F7: NA | G7: NA | H7: NA | I7: NA | J7: NA | K7: NA | L7: NA | M7: NA | N7: NA | O7: NA | P7: NA | Q7: NA | R7: NA | S7: NA | T7: NA | U7: NA | V7: NA | W7: NA | X7: NA | Y7: NA | Z7: NA | AA7: NA | AB7: NA | AC7: NA | AD7: NA | AE7: NA | AF7: NA | AG7: NA | AH7: NA | AI7: NA | AJ7: NA | AK7: NA | AL7: NA | AM7: NA | AN7: NA | AO7: NA | AP7: NA | AQ7: NA | AR7: NA | AS7: NA | AT7: NA | AU7: NA | AV7: NA | AW7: NA | AX7: NA | AY7: NA | AZ7: NA | BA7: NA | BB7: NA | BC7: NA | BD7: NA | BE7: NA
A8: S-PR-A-P3-C1-H1 | B8: =jaguaribe_80ml!B9/50 -> 0 | C8: =jaguaribe_80ml!C9/50 -> 0 | D8: =jaguaribe_80ml!D9/50 -> 2.64 | E8: =jaguaribe_80ml!E9/50 -> 0 | F8: =jaguaribe_80ml!F9/50 -> 44.1 | G8: =jaguaribe_80ml!G9/50 -> 0 | H8: =jaguaribe_80ml!H9/50 -> 0 | I8: =jaguaribe_80ml!I9/50 -> 93 | ... BE8: =jaguaribe_80ml!BE9/50 -> 0
A9: S-PR-A-P3-C1-H2 | B9: NA | C9: NA | D9: NA | E9: NA | F9: NA | G9: NA | H9: NA | I9: NA | J9: NA | K9: NA | L9: NA | M9: NA | N9: NA | O9: NA | P9: NA | Q9: NA | R9: NA | S9: NA | T9: NA | U9: NA | V9: NA | W9: NA | X9: NA | Y9: NA | Z9: NA | AA9: NA | AB9: NA | AC9: NA | AD9: NA | AE9: NA | AF9: NA | AG9: NA | AH9: NA | AI9: NA | AJ9: NA | AK9: NA | AL9: NA | AM9: NA | AN9: NA | AO9: NA | AP9: NA | AQ9: NA | AR9: NA | AS9: NA | AT9: NA | AU9: NA | AV9: NA | AW9: NA | AX9: NA | AY9: NA | AZ9: NA | BA9: NA | BB9: NA | BC9: NA | BD9: NA | BE9: NA
A10: S-PR-A-P3-C1-H3 | B10: NA | C10: NA | D10: NA | E10: NA | F10: NA | G10: NA | H10: NA | I10: NA | J10: NA | K10: NA | L10: NA | M10: NA | N10: NA | O10: NA | P10: NA | Q10: NA | R10: NA | S10: NA | T10: NA | U10: NA | V10: NA | W10: NA | X10: NA | Y10: NA | Z10: NA | AA10: NA | AB10: NA | AC10: NA | AD10: NA | AE10: NA | AF10: NA | AG10: NA | AH10: NA | AI10: NA | AJ10: NA | AK10: NA | AL10: NA | AM10: NA | AN10: NA | AO10: NA | AP10: NA | AQ10: NA | AR10: NA | AS10: NA | AT10: NA | AU10: NA | AV10: NA | AW10: NA | AX10: NA | AY10: NA | AZ10: NA | BA10: NA | BB10: NA | BC10: NA | BD10: NA | BE10: NA
A11: S-PR-M-P4-C1-H1 | B11: =jaguaribe_80ml!B12/50 -> 0 | C11: =jaguaribe_80ml!C12/50 -> 0 | D11: =jaguaribe_80ml!D12/50 -> 0.24 | E11: =jaguaribe_80ml!E12/50 -> 0 | F11: =jaguaribe_80ml!F12/50 -> 6.52 | G11: =jaguaribe_80ml!G12/50 -> 0 | H11: =jaguaribe_80ml!H12/50 -> 0 | I11: =jaguaribe_80ml!I12/50 -> 24.2 | ... BE11: =jaguaribe_80ml!BE12/50 -> 0
A12: S-PR-M-P4-C1-H2 | B12: NA | C12: NA | D12: NA | E12: NA | F12: NA | G12: NA | H12: NA | I12: NA | J12: NA | K12: NA | L12: NA | M12: NA | N12: NA | O12: NA | P12: NA | Q12: NA | R12: NA | S12: NA | T12: NA | U12: NA | V12: NA | W12: NA | X12: NA | Y12: NA | Z12: NA | AA12: NA | AB12: NA | AC12: NA | AD12: NA | AE12: NA | AF12: NA | AG12: NA | AH12: NA | AI12: NA | AJ12: NA | AK12: NA | AL12: NA | AM12: NA | AN12: NA | AO12: NA | AP12: NA | AQ12: NA | AR12: NA | AS12: NA | AT12: NA | AU12: NA | AV12: NA | AW12: NA | AX12: NA | AY12: NA | AZ12: NA | BA12: NA | BB12: NA | BC12: NA | BD12: NA | BE12: NA
A13: S-PR-M-P4-C1-H3 | B13: NA | C13: NA | D13: NA | E13: NA | F13: NA | G13: NA | H13: NA | I13: NA | J13: NA | K13: NA | L13: NA | M13: NA | N13: NA | O13: NA | P13: NA | Q13: NA | R13: NA | S13: NA | T13: NA | U13: NA | V13: NA | W13: NA | X13: NA | Y13: NA | Z13: NA | AA13: NA | AB13: NA | AC13: NA | AD13: NA | AE13: NA | AF13: NA | AG13: NA | AH13: NA | AI13: NA | AJ13: NA | AK13: NA | AL13: NA | AM13: NA | AN13: NA | AO13: NA | AP13: NA | AQ13: NA | AR13: NA | AS13: NA | AT13: NA | AU13: NA | AV13: NA | AW13: NA | AX13: NA | AY13: NA | AZ13: NA | BA13: NA | BB13: NA | BC13: NA | BD13: NA | BE13: NA
A14: S-PR-M-P5-C1-H1 | B14: =jaguaribe_80ml!B15/50 -> 0.02 | C14: =jaguaribe_80ml!C15/50 -> 0 | D14: =jaguaribe_80ml!D15/50 -> 1 | E14: =jaguaribe_80ml!E15/50 -> 0 | F14: =jaguaribe_80ml!F15/50 -> 3.36 | G14: =jaguaribe_80ml!G15/50 -> 0 | H14: =jaguaribe_80ml!H15/50 -> 0 | I14: =jaguaribe_80ml!I15/50 -> 4.3 | ... BE14: =jaguaribe_80ml!BE15/50 -> 0
A15: S-PR-M-P5-C1-H2 | B15: NA | C15: NA | D15: NA | E15: NA | F15: NA | G15: NA | H15: NA | I15: NA | J15: NA | K15: NA | L15: NA | M15: NA | N15: NA | O15: NA | P15: NA | Q15: NA | R15: NA | S15: NA | T15: NA | U15: NA | V15: NA | W15: NA | X15: NA | Y15: NA | Z15: NA | AA15: NA | AB15: NA | AC15: NA | AD15: NA | AE15: NA | AF15: NA | AG15: NA | AH15: NA | AI15: NA | AJ15: NA | AK15: NA | AL15: NA | AM15: NA | AN15: NA | AO15: NA | AP15: NA | AQ15: NA | AR15: NA | AS15: NA | AT15: NA | AU15: NA | AV15: NA | AW15: NA | AX15: NA | AY15: NA | AZ15: NA | BA15: NA | BB15: NA | BC15: NA | BD15: NA | BE15: NA
A16: S-PR-M-P5-C1-H3 | B16: NA | C16: NA | D16: NA | E16: NA | F16: NA | G16: NA | H16: NA | I16: NA | J16: NA | K16: NA | L16: NA | M16: NA | N16: NA | O16: NA | P16: NA | Q16: NA | R16: NA | S16: NA | T16: NA | U16: NA | V16: NA | W16: NA | X16: NA | Y16: NA | Z16: NA | AA16: NA | AB16: NA | AC16: NA | AD16: NA | AE16: NA | AF16: NA | AG16: NA | AH16: NA | AI16: NA | AJ16: NA | AK16: NA | AL16: NA | AM16: NA | AN16: NA | AO16: NA | AP16: NA | AQ16: NA | AR16: NA | AS16: NA | AT16: NA | AU16: NA | AV16: NA | AW16: NA | AX16: NA | AY16: NA | AZ16: NA | BA16: NA | BB16: NA | BC16: NA | BD16: NA | BE16: NA
A17: S-PR-M-P6-C1-H1 | B17: =jaguaribe_80ml!B18/50 -> 0.04 | C17: =jaguaribe_80ml!C18/50 -> 0 | D17: =jaguaribe_80ml!D18/50 -> 0.02 | E17: =jaguaribe_80ml!E18/50 -> 0 | F17: =jaguaribe_80ml!F18/50 -> 0.76 | G17: =jaguaribe_80ml!G18/50 -> 0 | H17: =jaguaribe_80ml!H18/50 -> 0 | I17: =jaguaribe_80ml!I18/50 -> 0.8 | ... BE17: =jaguaribe_80ml!BE18/50 -> 0
A18: S-PR-M-P6-C1-H2 | B18: NA | C18: NA | D18: NA | E18: NA | F18: NA | G18: NA | H18: NA | I18: NA | J18: NA | K18: NA | L18: NA | M18: NA | N18: NA | O18: NA | P18: NA | Q18: NA | R18: NA | S18: NA | T18: NA | U18: NA | V18: NA | W18: NA | X18: NA | Y18: NA | Z18: NA | AA18: NA | AB18: NA | AC18: NA | AD18: NA | AE18: NA | AF18: NA | AG18: NA | AH18: NA | AI18: NA | AJ18: NA | AK18: NA | AL18: NA | AM18: NA | AN18: NA | AO18: NA | AP18: NA | AQ18: NA | AR18: NA | AS18: NA | AT18: NA | AU18: NA | AV18: NA | AW18: NA | AX18: NA | AY18: NA | AZ18: NA | BA18: NA | BB18: NA | BC18: NA | BD18: NA | BE18: NA
A19: S-PR-M-P6-C1-H3 | B19: NA | C19: NA | D19: NA | E19: NA | F19: NA | G19: NA | H19: NA | I19: NA | J19: NA | K19: NA | L19: NA | M19: NA | N19: NA | O19: NA | P19: NA | Q19: NA | R19: NA | S19: NA | T19: NA | U19: NA | V19: NA | W19: NA | X19: NA | Y19: NA | Z19: NA | AA19: NA | AB19: NA | AC19: NA | AD19: NA | AE19: NA | AF19: NA | AG19: NA | AH19: NA | AI19: NA | AJ19: NA | AK19: NA | AL19: NA | AM19: NA | AN19: NA | AO19: NA | AP19: NA | AQ19: NA | AR19: NA | AS19: NA | AT19: NA | AU19: NA | AV19: NA | AW19: NA | AX19: NA | AY19: NA | AZ19: NA | BA19: NA | BB19: NA | BC19: NA | BD19: NA | BE19: NA
A20: S-PR-B-P7-C1-H1 | B20: =jaguaribe_80ml!B21/50 -> 0.06 | C20: =jaguaribe_80ml!C21/50 -> 0 | D20: =jaguaribe_80ml!D21/50 -> 0.54 | E20: =jaguaribe_80ml!E21/50 -> 0 | F20: =jaguaribe_80ml!F21/50 -> 0.26 | G20: =jaguaribe_80ml!G21/50 -> 0 | H20: =jaguaribe_80ml!H21/50 -> 0 | I20: =jaguaribe_80ml!I21/50 -> 0.76 | ... BE20: =jaguaribe_80ml!BE21/50 -> 0
A21: S-PR-B-P7-C1-H2 | B21: NA | C21: NA | D21: NA | E21: NA | F21: NA | G21: NA | H21: NA | I21: NA | J21: NA | K21: NA | L21: NA | M21: NA | N21: NA | O21: NA | P21: NA | Q21: NA | R21: NA | S21: NA | T21: NA | U21: NA | V21: NA | W21: NA | X21: NA | Y21: NA | Z21: NA | AA21: NA | AB21: NA | AC21: NA | AD21: NA | AE21: NA | AF21: NA | AG21: NA | AH21: NA | AI21: NA | AJ21: NA | AK21: NA | AL21: NA | AM21: NA | AN21: NA | AO21: NA | AP21: NA | AQ21: NA | AR21: NA | AS21: NA | AT21: NA | AU21: NA | AV21: NA | AW21: NA | AX21: NA | AY21: NA | AZ21: NA | BA21: NA | BB21: NA | BC21: NA | BD21: NA | BE21: NA
A22: S-PR-B-P7-C1-H3 | B22: NA | C22: NA | D22: NA | E22: NA | F22: NA | G22: NA | H22: NA | I22: NA | J22: NA | K22: NA | L22: NA | M22: NA | N22: NA | O22: NA | P22: NA | Q22: NA | R22: NA | S22: NA | T22: NA | U22: NA | V22: NA | W22: NA | X22: NA | Y22: NA | Z22: NA | AA22: NA | AB22: NA | AC22: NA | AD22: NA | AE22: NA | AF22: NA | AG22: NA | AH22: NA | AI22: NA | AJ22: NA | AK22: NA | AL22: NA | AM22: NA | AN22: NA | AO22: NA | AP22: NA | AQ22: NA | AR22: NA | AS22: NA | AT22: NA | AU22: NA | AV22: NA | AW22: NA | AX22: NA | AY22: NA | AZ22: NA | BA22: NA | BB22: NA | BC22: NA | BD22: NA | BE22: NA
A23: S-PR-B-P8-C1-H1 | B23: =jaguaribe_80ml!B24/50 -> 0 | C23: =jaguaribe_80ml!C24/50 -> 0 | D23: =jaguaribe_80ml!D24/50 -> 0.24 | E23: =jaguaribe_80ml!E24/50 -> 0 | F23: =jaguaribe_80ml!F24/50 -> 11.82 | G23: =jaguaribe_80ml!G24/50 -> 2.1 | H23: =jaguaribe_80ml!H24/50 -> 0 | I23: =jaguaribe_80ml!I24/50 -> 0.78 | ... BE23: =jaguaribe_80ml!BE24/50 -> 0
A24: S-PR-B-P8-C1-H2 | B24: NA | C24: NA | D24: NA | E24: NA | F24: NA | G24: NA | H24: NA | I24: NA | J24: NA | K24: NA | L24: NA | M24: NA | N24: NA | O24: NA | P24: NA | Q24: NA | R24: NA | S24: NA | T24: NA | U24: NA | V24: NA | W24: NA | X24: NA | Y24: NA | Z24: NA | AA24: NA | AB24: NA | AC24: NA | AD24: NA | AE24: NA | AF24: NA | AG24: NA | AH24: NA | AI24: NA | AJ24: NA | AK24: NA | AL24: NA | AM24: NA | AN24: NA | AO24: NA | AP24: NA | AQ24: NA | AR24: NA | AS24: NA | AT24: NA | AU24: NA | AV24: NA | AW24: NA | AX24: NA | AY24: NA | AZ24: NA | BA24: NA | BB24: NA | BC24: NA | BD24: NA | BE24: NA
A25: S-PR-B-P8-C1-H3 | B25: NA | C25: NA | D25: NA | E25: NA | F25: NA | G25: NA | H25: NA | I25: NA | J25: NA | K25: NA | L25: NA | M25: NA | N25: NA | O25: NA | P25: NA | Q25: NA | R25: NA | S25: NA | T25: NA | U25: NA | V25: NA | W25: NA | X25: NA | Y25: NA | Z25: NA | AA25: NA | AB25: NA | AC25: NA | AD25: NA | AE25: NA | AF25: NA | AG25: NA | AH25: NA | AI25: NA | AJ25: NA | AK25: NA | AL25: NA | AM25: NA | AN25: NA | AO25: NA | AP25: NA | AQ25: NA | AR25: NA | AS25: NA | AT25: NA | AU25: NA | AV25: NA | AW25: NA | AX25: NA | AY25: NA | AZ25: NA | BA25: NA | BB25: NA | BC25: NA | BD25: NA | BE25: NA
A26: S-PR-B-P9-C1-H1 | B26: =jaguaribe_80ml!B27/50 -> 0 | C26: =jaguaribe_80ml!C27/50 -> 0 | D26: =jaguaribe_80ml!D27/50 -> 42.3 | E26: =jaguaribe_80ml!E27/50 -> 0 | F26: =jaguaribe_80ml!F27/50 -> 54.72 | G26: =jaguaribe_80ml!G27/50 -> 0.24 | H26: =jaguaribe_80ml!H27/50 -> 0 | I26: =jaguaribe_80ml!I27/50 -> 1.68 | ... BE26: =jaguaribe_80ml!BE27/50 -> 0
A27: S-PR-B-P9-C1-H2 | B27: NA | C27: NA | D27: NA | E27: NA | F27: NA | G27: NA | H27: NA | I27: NA | J27: NA | K27: NA | L27: NA | M27: NA | N27: NA | O27: NA | P27: NA | Q27: NA | R27: NA | S27: NA | T27: NA | U27: NA | V27: NA | W27: NA | X27: NA | Y27: NA | Z27: NA | AA27: NA | AB27: NA | AC27: NA | AD27: NA | AE27: NA | AF27: NA | AG27: NA | AH27: NA | AI27: NA | AJ27: NA | AK27: NA | AL27: NA | AM27: NA | AN27: NA | AO27: NA | AP27: NA | AQ27: NA | AR27: NA | AS27: NA | AT27: NA | AU27: NA | AV27: NA | AW27: NA | AX27: NA | AY27: NA | AZ27: NA | BA27: NA | BB27: NA | BC27: NA | BD27: NA | BE27: NA
A28: S-PR-B-P9-C1-H3 | B28: NA | C28: NA | D28: NA | E28: NA | F28: NA | G28: NA | H28: NA | I28: NA | J28: NA | K28: NA | L28: NA | M28: NA | N28: NA | O28: NA | P28: NA | Q28: NA | R28: NA | S28: NA | T28: NA | U28: NA | V28: NA | W28: NA | X28: NA | Y28: NA | Z28: NA | AA28: NA | AB28: NA | AC28: NA | AD28: NA | AE28: NA | AF28: NA | AG28: NA | AH28: NA | AI28: NA | AJ28: NA | AK28: NA | AL28: NA | AM28: NA | AN28: NA | AO28: NA | AP28: NA | AQ28: NA | AR28: NA | AS28: NA | AT28: NA | AU28: NA | AV28: NA | AW28: NA | AX28: NA | AY28: NA | AZ28: NA | BA28: NA | BB28: NA | BC28: NA | BD28: NA | BE28: NA
A29: C-PR-A-P1-C2-H1 | B29: =jaguaribe_80ml!B30/50 -> 0 | C29: =jaguaribe_80ml!C30/50 -> 0 | D29: =jaguaribe_80ml!D30/50 -> 2.6 | E29: =jaguaribe_80ml!E30/50 -> 0 | F29: =jaguaribe_80ml!F30/50 -> 0.06 | G29: =jaguaribe_80ml!G30/50 -> 0 | H29: =jaguaribe_80ml!H30/50 -> 0 | I29: =jaguaribe_80ml!I30/50 -> 0.12 | ... BE29: =jaguaribe_80ml!BE30/50 -> 0
A30: C-PR-A-P1-C2-H2 | B30: =jaguaribe_80ml!B31/50 -> 0 | C30: =jaguaribe_80ml!C31/50 -> 0 | D30: =jaguaribe_80ml!D31/50 -> 0.8 | E30: =jaguaribe_80ml!E31/50 -> 0 | F30: =jaguaribe_80ml!F31/50 -> 0.08 | G30: =jaguaribe_80ml!G31/50 -> 0 | H30: =jaguaribe_80ml!H31/50 -> 0 | I30: =jaguaribe_80ml!I31/50 -> 0.04 | ... BE30: =jaguaribe_80ml!BE31/50 -> 0
A31: C-PR-A-P1-C2-H3 | B31: =jaguaribe_80ml!B32/50 -> 0 | C31: =jaguaribe_80ml!C32/50 -> 0 | D31: =jaguaribe_80ml!D32/50 -> 0.22 | E31: =jaguaribe_80ml!E32/50 -> 0 | F31: =jaguaribe_80ml!F32/50 -> 0 | G31: =jaguaribe_80ml!G32/50 -> 0 | H31: =jaguaribe_80ml!H32/50 -> 0 | I31: =jaguaribe_80ml!I32/50 -> 0 | ... BE31: =jaguaribe_80ml!BE32/50 -> 0
A32: C-PR-A-P2-C2-H1 | B32: =jaguaribe_80ml!B33/50 -> 0 | C32: =jaguaribe_80ml!C33/50 -> 0 | D32: =jaguaribe_80ml!D33/50 -> 0.4 | E32: =jaguaribe_80ml!E33/50 -> 0 | F32: =jaguaribe_80ml!F33/50 -> 0 | G32: =jaguaribe_80ml!G33/50 -> 0.04 | H32: =jaguaribe_80ml!H33/50 -> 0.02 | I32: =jaguaribe_80ml!I33/50 -> 0.04 | ... BE32: =jaguaribe_80ml!BE33/50 -> 0
A33: C-PR-A-P2-C2-H2 | B33: =jaguaribe_80ml!B34/50 -> 0 | C33: =jaguaribe_80ml!C34/50 -> 0 | D33: =jaguaribe_80ml!D34/50 -> 0.14 | E33: =jaguaribe_80ml!E34/50 -> 0 | F33: =jaguaribe_80ml!F34/50 -> 0.02 | G33: =jaguaribe_80ml!G34/50 -> 0.02 | H33: =jaguaribe_80ml!H34/50 -> 0 | I33: =jaguaribe_80ml!I34/50 -> 0.02 | ... BE33: =jaguaribe_80ml!BE34/50 -> 0.02
A34: C-PR-A-P2-C2-H3 | B34: =jaguaribe_80ml!B35/50 -> 0 | C34: =jaguaribe_80ml!C35/50 -> 0 | D34: =jaguaribe_80ml!D35/50 -> 0.24 | E34: =jaguaribe_80ml!E35/50 -> 0 | F34: =jaguaribe_80ml!F35/50 -> 0 | G34: =jaguaribe_80ml!G35/50 -> 0.06 | H34: =jaguaribe_80ml!H35/50 -> 0.02 | I34: =jaguaribe_80ml!I35/50 -> 0.06 | ... BE34: =jaguaribe_80ml!BE35/50 -> 0
A35: C-PR-A-P3-C2-H1 | B35: =jaguaribe_80ml!B36/50 -> 0.02 | C35: =jaguaribe_80ml!C36/50 -> 0 | D35: =jaguaribe_80ml!D36/50 -> 0.2 | E35: =jaguaribe_80ml!E36/50 -> 0.32 | F35: =jaguaribe_80ml!F36/50 -> 0.2 | G35: =jaguaribe_80ml!G36/50 -> 0 | H35: =jaguaribe_80ml!H36/50 -> 1.6 | I35: =jaguaribe_80ml!I36/50 -> 0.02 | ... BE35: =jaguaribe_80ml!BE36/50 -> 0
A36: C-PR-A-P3-C2-H2 | B36: =jaguaribe_80ml!B37/50 -> 0 | C36: =jaguaribe_80ml!C37/50 -> 0 | D36: =jaguaribe_80ml!D37/50 -> 0.08 | E36: =jaguaribe_80ml!E37/50 -> 0.56 | F36: =jaguaribe_80ml!F37/50 -> 0.32 | G36: =jaguaribe_80ml!G37/50 -> 0 | H36: =jaguaribe_80ml!H37/50 -> 1.56 | I36: =jaguaribe_80ml!I37/50 -> 0 | ... BE36: =jaguaribe_80ml!BE37/50 -> 0
A37: C-PR-A-P3-C2-H3 | B37: =jaguaribe_80ml!B38/50 -> 0 | C37: =jaguaribe_80ml!C38/50 -> 0 | D37: =jaguaribe_80ml!D38/50 -> 0.04 | E37: =jaguaribe_80ml!E38/50 -> 2.22 | F37: =jaguaribe_80ml!F38/50 -> 0.4 | G37: =jaguaribe_80ml!G38/50 -> 0.22 | H37: =jaguaribe_80ml!H38/50 -> 2.7 | I37: =jaguaribe_80ml!I38/50 -> 0.02 | ... BE37: =jaguaribe_80ml!BE38/50 -> 0
A38: C-PR-M-P4-C2-H1 | B38: =jaguaribe_80ml!B39/50 -> 0 | C38: =jaguaribe_80ml!C39/50 -> 0 | D38: =jaguaribe_80ml!D39/50 -> 0.28 | E38: =jaguaribe_80ml!E39/50 -> 1.54 | F38: =jaguaribe_80ml!F39/50 -> 0.16 | G38: =jaguaribe_80ml!G39/50 -> 0.08 | H38: =jaguaribe_80ml!H39/50 -> 1.68 | I38: =jaguaribe_80ml!I39/50 -> 0.04 | ... BE38: =jaguaribe_80ml!BE39/50 -> 0
A39: C-PR-M-P4-C2-H2 | B39: =jaguaribe_80ml!B40/50 -> 0 | C39: =jaguaribe_80ml!C40/50 -> 0 | D39: =jaguaribe_80ml!D40/50 -> 0.08 | E39: =jaguaribe_80ml!E40/50 -> 0.76 | F39: =jaguaribe_80ml!F40/50 -> 0.3 | G39: =jaguaribe_80ml!G40/50 -> 0.06 | H39: =jaguaribe_80ml!H40/50 -> 1.42 | I39: =jaguaribe_80ml!I40/50 -> 0.02 | ... BE39: =jaguaribe_80ml!BE40/50 -> 0
A40: C-PR-M-P4-C2-H3 | B40: =jaguaribe_80ml!B41/50 -> 0 | C40: =jaguaribe_80ml!C41/50 -> 0 | D40: =jaguaribe_80ml!D41/50 -> 0.06 | E40: =jaguaribe_80ml!E41/50 -> 0.76 | F40: =jaguaribe_80ml!F41/50 -> 0.36 | G40: =jaguaribe_80ml!G41/50 -> 0.02 | H40: =jaguaribe_80ml!H41/50 -> 1.08 | I40: =jaguaribe_80ml!I41/50 -> 0 | ... BE40: =jaguaribe_80ml!BE41/50 -> 0
...

Sheet densidade_ponto_indL
B1: =jaguaribe_80ml!B2 -> Alo.isabellae | C1: =jaguaribe_80ml!C2 -> Bia.ossiani | D1: =jaguaribe_80ml!D2 -> Bdelloidea | E1: =jaguaribe_80ml!E2 -> Bra.angularis | F1: =jaguaribe_80ml!F2 -> Bra.calyciflorus | G1: =jaguaribe_80ml!G2 -> Bra.caudatus | H1: =jaguaribe_80ml!H2 -> Bra.falcatus | I1: =jaguaribe_80ml!I2 -> Bra. Havanaensis | ... BE1: =jaguaribe_80ml!BE2 -> Tri.tetractis
A2: S-PR-A-P1-C1 | B2: =AVERAGE(densidade_hab_indL!B2) -> 0 | C2: =AVERAGE(densidade_hab_indL!C2) -> 0 | D2: =AVERAGE(densidade_hab_indL!D2) -> 0.78 | E2: =AVERAGE(densidade_hab_indL!E2) -> 0 | F2: =AVERAGE(densidade_hab_indL!F2) -> 0 | G2: =AVERAGE(densidade_hab_indL!G2) -> 0 | H2: =AVERAGE(densidade_hab_indL!H2) -> 0 | I2: =AVERAGE(densidade_hab_indL!I2) -> 0 | ... BE2: =AVERAGE(densidade_hab_indL!BE2) -> 0
A3: S-PR-A-P2-C1 | B3: =AVERAGE(densidade_hab_indL!B5) -> 0 | C3: =AVERAGE(densidade_hab_indL!C5) -> 0 | D3: =AVERAGE(densidade_hab_indL!D5) -> 0.82 | E3: =AVERAGE(densidade_hab_indL!E5) -> 0 | F3: =AVERAGE(densidade_hab_indL!F5) -> 0 | G3: =AVERAGE(densidade_hab_indL!G5) -> 0 | H3: =AVERAGE(densidade_hab_indL!H5) -> 0 | I3: =AVERAGE(densidade_hab_indL!I5) -> 0 | ... BE3: =AVERAGE(densidade_hab_indL!BE5) -> 0
A4: S-PR-A-P3-C1 | B4: =AVERAGE(densidade_hab_indL!B8) -> 0 | C4: =AVERAGE(densidade_hab_indL!C8) -> 0 | D4: =AVERAGE(densidade_hab_indL!D8) -> 2.64 | E4: =AVERAGE(densidade_hab_indL!E8) -> 0 | F4: =AVERAGE(densidade_hab_indL!F8) -> 44.1 | G4: =AVERAGE(densidade_hab_indL!G8) -> 0 | H4: =AVERAGE(densidade_hab_indL!H8) -> 0 | I4: =AVERAGE(densidade_hab_indL!I8) -> 93 | ... BE4: =AVERAGE(densidade_hab_indL!BE8) -> 0
A5: S-PR-M-P4-C1 | B5: =AVERAGE(densidade_hab_indL!B11) -> 0 | C5: =AVERAGE(densidade_hab_indL!C11) -> 0 | D5: =AVERAGE(densidade_hab_indL!D11) -> 0.24 | E5: =AVERAGE(densidade_hab_indL!E11) -> 0 | F5: =AVERAGE(densidade_hab_indL!F11) -> 6.52 | G5: =AVERAGE(densidade_hab_indL!G11) -> 0 | H5: =AVERAGE(densidade_hab_indL!H11) -> 0 | I5: =AVERAGE(densidade_hab_indL!I11) -> 24.2 | ... BE5: =AVERAGE(densidade_hab_indL!BE11) -> 0
A6: S-PR-M-P5-C1 | B6: =AVERAGE(densidade_hab_indL!B14) -> 0.02 | C6: =AVERAGE(densidade_hab_indL!C14) -> 0 | D6: =AVERAGE(densidade_hab_indL!D14) -> 1 | E6: =AVERAGE(densidade_hab_indL!E14) -> 0 | F6: =AVERAGE(densidade_hab_indL!F14) -> 3.36 | G6: =AVERAGE(densidade_hab_indL!G14) -> 0 | H6: =AVERAGE(densidade_hab_indL!H14) -> 0 | I6: =AVERAGE(densidade_hab_indL!I14) -> 4.3 | ... BE6: =AVERAGE(densidade_hab_indL!BE14) -> 0
A7: S-PR-M-P6-C1 | B7: =AVERAGE(densidade_hab_indL!B17) -> 0.04 | C7: =AVERAGE(densidade_hab_indL!C17) -> 0 | D7: =AVERAGE(densidade_hab_indL!D17) -> 0.02 | E7: =AVERAGE(densidade_hab_indL!E17) -> 0 | F7: =AVERAGE(densidade_hab_indL!F17) -> 0.76 | G7: =AVERAGE(densidade_hab_indL!G17) -> 0 | H7: =AVERAGE(densidade_hab_indL!H17) -> 0 | I7: =AVERAGE(densidade_hab_indL!I17) -> 0.8 | ... BE7: =AVERAGE(densidade_hab_indL!BE17) -> 0
A8: S-PR-B-P7-C1 | B8: =AVERAGE(densidade_hab_indL!B20) -> 0.06 | C8: =AVERAGE(densidade_hab_indL!C20) -> 0 | D8: =AVERAGE(densidade_hab_indL!D20) -> 0.54 | E8: =AVERAGE(densidade_hab_indL!E20) -> 0 | F8: =AVERAGE(densidade_hab_indL!F20) -> 0.26 | G8: =AVERAGE(densidade_hab_indL!G20) -> 0 | H8: =AVERAGE(densidade_hab_indL!H20) -> 0 | I8: =AVERAGE(densidade_hab_indL!I20) -> 0.76 | ... BE8: =AVERAGE(densidade_hab_indL!BE20) -> 0
A9: S-PR-B-P8-C1 | B9: =AVERAGE(densidade_hab_indL!B23) -> 0 | C9: =AVERAGE(densidade_hab_indL!C23) -> 0 | D9: =AVERAGE(densidade_hab_indL!D23) -> 0.24 | E9: =AVERAGE(densidade_hab_indL!E23) -> 0 | F9: =AVERAGE(densidade_hab_indL!F23) -> 11.82 | G9: =AVERAGE(densidade_hab_indL!G23) -> 2.1 | H9: =AVERAGE(densidade_hab_indL!H23) -> 0 | I9: =AVERAGE(densidade_hab_indL!I23) -> 0.78 | ... BE9: =AVERAGE(densidade_hab_indL!BE23) -> 0
A10: S-PR-B-P9-C1 | B10: =AVERAGE(densidade_hab_indL!B26) -> 0 | C10: =AVERAGE(densidade_hab_indL!C26) -> 0 | D10: =AVERAGE(densidade_hab_indL!D26) -> 42.3 | E10: =AVERAGE(densidade_hab_indL!E26) -> 0 | F10: =AVERAGE(densidade_hab_indL!F26) -> 54.72 | G10: =AVERAGE(densidade_hab_indL!G26) -> 0.24 | H10: =AVERAGE(densidade_hab_indL!H26) -> 0 | I10: =AVERAGE(densidade_hab_indL!I26) -> 1.68 | ... BE10: =AVERAGE(densidade_hab_indL!BE26) -> 0
A11: C-PR-A-P1-C2 | B11: =AVERAGE(densidade_hab_indL!B29:B31) -> 0 | C11: =AVERAGE(densidade_hab_indL!C29:C31) -> 0 | D11: =AVERAGE(densidade_hab_indL!D29:D31) -> 1.2066667 | E11: =AVERAGE(densidade_hab_indL!E29:E31) -> 0 | F11: =AVERAGE(densidade_hab_indL!F29:F31) -> 0.046666667 | G11: =AVERAGE(densidade_hab_indL!G29:G31) -> 0 | H11: =AVERAGE(densidade_hab_indL!H29:H31) -> 0 | I11: =AVERAGE(densidade_hab_indL!I29:I31) -> 0.053333333 | ... BE11: =AVERAGE(densidade_hab_indL!BE29:BE31) -> 0
A12: C-PR-A-P2-C2 | B12: =AVERAGE(densidade_hab_indL!B32:B34) -> 0 | C12: =AVERAGE(densidade_hab_indL!C32:C34) -> 0 | D12: =AVERAGE(densidade_hab_indL!D32:D34) -> 0.26 | E12: =AVERAGE(densidade_hab_indL!E32:E34) -> 0 | F12: =AVERAGE(densidade_hab_indL!F32:F34) -> 0.0066666667 | G12: =AVERAGE(densidade_hab_indL!G32:G34) -> 0.04 | H12: =AVERAGE(densidade_hab_indL!H32:H34) -> 0.013333333 | I12: =AVERAGE(densidade_hab_indL!I32:I34) -> 0.04 | ... BE12: =AVERAGE(densidade_hab_indL!BE32:BE34) -> 0.0066666667
A13: C-PR-A-P3-C2 | B13: =AVERAGE(densidade_hab_indL!B35:B37) -> 0.0066666667 | C13: =AVERAGE(densidade_hab_indL!C35:C37) -> 0 | D13: =AVERAGE(densidade_hab_indL!D35:D37) -> 0.10666667 | E13: =AVERAGE(densidade_hab_indL!E35:E37) -> 1.0333333 | F13: =AVERAGE(densidade_hab_indL!F35:F37) -> 0.30666667 | G13: =AVERAGE(densidade_hab_indL!G35:G37) -> 0.073333333 | H13: =AVERAGE(densidade_hab_indL!H35:H37) -> 1.9533333 | I13: =AVERAGE(densidade_hab_indL!I35:I37) -> 0.013333333 | ... BE13: =AVERAGE(densidade_hab_indL!BE35:BE37) -> 0
A14: C-PR-M-P4-C2 | B14: =AVERAGE(densidade_hab_indL!B38:B40) -> 0 | C14: =AVERAGE(densidade_hab_indL!C38:C40) -> 0 | D14: =AVERAGE(densidade_hab_indL!D38:D40) -> 0.14 | E14: =AVERAGE(densidade_hab_indL!E38:E40) -> 1.02 | F14: =AVERAGE(densidade_hab_indL!F38:F40) -> 0.27333333 | G14: =AVERAGE(densidade_hab_indL!G38:G40) -> 0.053333333 | H14: =AVERAGE(densidade_hab_indL!H38:H40) -> 1.3933333 | I14: =AVERAGE(densidade_hab_indL!I38:I40) -> 0.02 | ... BE14: =AVERAGE(densidade_hab_indL!BE38:BE40) -> 0
A15: C-PR-M-P5-C2 | B15: =AVERAGE(densidade_hab_indL!B41:B43) -> 0 | C15: =AVERAGE(densidade_hab_indL!C41:C43) -> 0 | D15: =AVERAGE(densidade_hab_indL!D41:D43) -> 0.06 | E15: =AVERAGE(densidade_hab_indL!E41:E43) -> 0.02 | F15: =AVERAGE(densidade_hab_indL!F41:F43) -> 0.046666667 | G15: =AVERAGE(densidade_hab_indL!G41:G43) -> 0.013333333 | H15: =AVERAGE(densidade_hab_indL!H41:H43) -> 0.23333333 | I15: =AVERAGE(densidade_hab_indL!I41:I43) -> 0 | ... BE15: =AVERAGE(densidade_hab_indL!BE41:BE43) -> 0
A16: C-PR-M-P6-C2 | B16: =AVERAGE(densidade_hab_indL!B44:B46) -> 0 | C16: =AVERAGE(densidade_hab_indL!C44:C46) -> 0 | D16: =AVERAGE(densidade_hab_indL!D44:D46) -> 0.093333333 | E16: =AVERAGE(densidade_hab_indL!E44:E46) -> 0 | F16: =AVERAGE(densidade_hab_indL!F44:F46) -> 0.88666667 | G16: =AVERAGE(densidade_hab_indL!G44:G46) -> 0 | H16: =AVERAGE(densidade_hab_indL!H44:H46) -> 0.0066666667 | I16: =AVERAGE(densidade_hab_indL!I44:I46) -> 0.68666667 | ... BE16: =AVERAGE(densidade_hab_indL!BE44:BE46) -> 0
A17: C-PR-B-P7-C2 | B17: =AVERAGE(densidade_hab_indL!B47:B49) -> 0 | C17: =AVERAGE(densidade_hab_indL!C47:C49) -> 0.0066666667 | D17: =AVERAGE(densidade_hab_indL!D47:D49) -> 0.21333333 | E17: =AVERAGE(densidade_hab_indL!E47:E49) -> 0 | F17: =AVERAGE(densidade_hab_indL!F47:F49) -> 0.04 | G17: =AVERAGE(densidade_hab_indL!G47:G49) -> 0 | H17: =AVERAGE(densidade_hab_indL!H47:H49) -> 0 | I17: =AVERAGE(densidade_hab_indL!I47:I49) -> 0.046666667 | ... BE17: =AVERAGE(densidade_hab_indL!BE47:BE49) -> 0
A18: C-PR-B-P8-C2 | B18: =AVERAGE(densidade_hab_indL!B50:B52) -> 0 | C18: =AVERAGE(densidade_hab_indL!C50:C52) -> 0 | D18: =AVERAGE(densidade_hab_indL!D50:D52) -> 0.50666667 | E18: =AVERAGE(densidade_hab_indL!E50:E52) -> 0.066666667 | F18: =AVERAGE(densidade_hab_indL!F50:F52) -> 1.6466667 | G18: =AVERAGE(densidade_hab_indL!G50:G52) -> 0.013333333 | H18: =AVERAGE(densidade_hab_indL!H50:H52) -> 1.3666667 | I18: =AVERAGE(densidade_hab_indL!I50:I52) -> 0.013333333 | ... BE18: =AVERAGE(densidade_hab_indL!BE50:BE52) -> 0
A19: C-PR-B-P9-C2 | B19: =AVERAGE(densidade_hab_indL!B53:B55) -> 0 | C19: =AVERAGE(densidade_hab_indL!C53:C55) -> 0 | D19: =AVERAGE(densidade_hab_indL!D53:D55) -> 3.46 | E19: =AVERAGE(densidade_hab_indL!E53:E55) -> 0.06 | F19: =AVERAGE(densidade_hab_indL!F53:F55) -> 2.6866667 | G19: =AVERAGE(densidade_hab_indL!G53:G55) -> 0.033333333 | H19: =AVERAGE(densidade_hab_indL!H53:H55) -> 0.066666667 | I19: =AVERAGE(densidade_hab_indL!I53:I55) -> 0.013333333 | ... BE19: =AVERAGE(densidade_hab_indL!BE53:BE55) -> 0
A20: S-PS-A-P1-C3
A21: S-PS-A-P2-C3
A22: S-PS-A-P3-C3
A23: S-PS-M-P4-C3
A24: S-PS-M-P5-C3
A25: S-PS-M-P6-C3
A26: S-PS-B-P7-C3
A27: S-PS-B-P8-C3
A28: S-PS-B-P9-C3
A29: C-PS-A-P1-C4
A30: C-PS-A-P2-C4
A31: C-PS-A-P3-C4
... A46: S-PS-B-P9-C1

Sheet codes
A1: DESENHO AMOSTRAL DE ZOOPLÂNCTON
C2: 3 | D2: bacias* | E2: = segmento | F2: *alto, médio e baixo
C3: 9 | D3: pontos | J3: vermelho | K3: errado ou conferir
C4: 3 | D4: potes por ponto | J4: verde | K4: conferido
C5: 5 | D5: coletas | J5: azul | K5: dados novos
C7: =C5*C4*C3 -> 135 | D7: amostras | J7: Tags
F8: No. Da coleta | J8: Período | L8: x | M8: x | N8: x | O8: x
C9: Antes | D9: 43739 | E9: seco | F9: 1 | J9: S- | K9: Transposição | M9: x | N9: x | O9: x
D10: 43891 | E10: chuvoso | F10: 2 | J10: C- | K10: PR | L10: Segmento | M10: x | N10: x | O10: x
C11: Depois | D11: 44501 | E11: seco | F11: 3 | J11: x | K11: PS | L11: A | M11: Ponto | N11: x | O11: x
D12: 44682 | E12: chuvoso | F12: 4 | J12: x | K12: x | L12: M | M12: 1 | N12: Habitat* | O12: x
D13: 45962 | E13: seco | F13: 1 | J13: x | K13: x | L13: B | M13: 2 | N13: 1 | O13: Coleta
E14: chuvoso | J14: x | K14: x | L14: x | M14: 3 | N14: 2 | O14: 1
J15: x | K15: x | L15: x | M15: 4 | N15: 3 | O15: 2
D16: local | J16: x | K16: x | L16: x | M16: 5 | N16: x | O16: 3
A17: Ponto 1-3 | B17: Alto | C17: Ponto 1 | D17: jati/ce | J17: x | K17: x | L17: x | M17: 6 | N17: x | O17: 4
A18: Ponto 4-6 | B18: Médio | C18: Ponto 2 | D18: aurora/ce | J18: x | K18: x | L18: x | M18: 7 | N18: x | O18: x
A19: Ponto 7-9 | B19: Baixo | C19: Ponto 3 | D19: ico/ce | J19: x | K19: x | L19: x | M19: 8 | N19: x | O19: x
C20: Ponto 4 | D20: ico/ce | J20: x | K20: x | L20: x | M20: 9 | N20: x | O20: x
C21: Ponto 5 | D21: jaguaribe
C22: Ponto 6 | D22: sjjaguaribe | J22: *habitat | K22: =réplica, pote
C23: Ponto 7 | D23: quixere
C24: Ponto 8 | D24: russas
C25: Ponto 9 | D25: jaguaruana

Sheet Espécies
A1: TOTAL JAGUARIBE | F1: Lista de acordo com:
A2: ="total = "&SUM(B4:B92) -> total = 59 | C2: ROTIFERA | F2: https://www.gbif.org/
A3: ="Rotifera = "&SUM(B3:B61) -> Rotifera = 41 | C3: DIGONONTA | F3: https://www.nies.go.jp/chiiki1/protoz/index.html
A4: ="Cladocera = "&SUM(B65:B82) -> Cladocera = 14 | B4: 1 | C4: Bdelloidea | D4: Bdelloidea | F4: https://www.nies.go.jp/chiiki1/protoz/identi-r.htm
A5: ="Copepoda = "&SUM(B83:B92) -> Copepoda = 4 | B5: 0 | C5: Notommatidae | F5: https://www.marinespecies.org/index.php
A6: ="Rot spp = "&SUM(B5:B61) -> Rot spp = 40 | B6: 1 | C6: Cephalodella sp. | D6: Cephalodella.sp | F6: https://cladocera.wordpress.com/
A7: ="Rot fam = "&COUNTIF(B4:B61,"0") -> Rot fam = 17 | B7: 0 | C7: MONOGONONTA | F7: https://rotifera.aphia.org/
A8: ="Bra = "&SUM(B11:B27) -> Bra = 16 | B8: 0 | C8: PLOIMA
A9: ="Lec = "&SUM(B32:B42) -> Lec = 10 | B9: 0 | C9: Asplanchnidae
A10: ="Chy = "&SUM(B65:B76) -> Chy = 11 | B10: 1 | C10: Asplanchna sp. | D10: Asplanchna.sp
B11: 0 | C11: Brachionidae
B12: 1 | C12: Brachionus angularis Gosse, 1851 | D12: Bra.angularis
B13: 1 | C13: Brachionus calyciflorus Pallas, 1766 | D13: Bra.calyciflorus
B14: 1 | C14: Brachionus caudatus Barrois & Daday, 1894 | D14: Bra.caudatus
B15: 1 | C15: Brachionus falcatus Zacharias, 1898 | D15: Bra.falcatus
B16: 1 | C16: Brachionus havanaensis Rousselet, 1911 | D16: Bra.havanaensis
B17: 1 | C17: Brachionus quadridentatus Hermann, 1783 | D17: Bra.quadridentatus
B18: 1 | C18: Brachionus plicatilis Müller, 1786 | D18: Bra.plicatilis
B19: 1 | C19: Brachionus urceolaris Müller, 1773 | D19: Bra.urceolaris
B20: 1 | C20: Keratella americana Carlin, 1943 | D20: Ker.americana
B21: 1 | C21: Keratella cochlearis (Gosse, 1851) | D21: Ker.cochlearis
B22: 1 | C22: Keratella lenzi Hauer, 1953 | D22: Ker.lenzi
B23: 1 | C23: Keratella tropica (Apstein, 1907) | D23: Ker.tropica
... B27: 1 | C27: Platyias quadricornis (Ehrenberg, 1832) | D27: Pla.quadricornis
B28: 0 | C28: Dicranophoridae
B29: 1 | C29: Dicranophorus sp. | D29: Dicranophorus.sp
B30: 0 | C30: Epiphanidae
B31: 1 | C31: Epiphanes macroura (Barrois & Daday, 1894) | D31: Epi.macroura
B32: 0 | C32: Lecanidae
B33: 1 | C33: Lecane aculeata (Jakubski, 1912) | D33: Lec.aculeata
B34: 1 | C34: Lecane bulla (Gosse, 1851) | D34: Lec.bulla
B35: 1 | C35: Lecane cornuta (Müller, 1786) | D35: Lec.cornuta
B36: 1 | C36: Lecane curvicornis (Murray, 1913) | D36: Lec.curvicornis
B37: 1 | C37: Lecane furcata (Murray, 1913) | D37: Lec.furcata
B38: 1 | C38: Lecane leontina (Turner, 1892) | D38: Lec.leontina
B39: 1 | C39: Lecane luna (Müller, 1776) | D39: Lec.luna
B40: 1 | C40: Lecane lunaris (Ehrenberg, 1832) | D40: Lec.lunaris
B41: 1 | C41: Lecane papuana (Murray, 1913) | D41: Lec.papuana
B42: 1 | C42: Lecane quadridentata (Ehrenberg, 1830) | D42: Lec.quadridentata
B43: 0 | C43: Lepadellidae
...
